[2025-04-03T09:22:00.188+0000] {local_task_job_runner.py:123} INFO - ::group::Pre task execution logs
[2025-04-03T09:22:00.221+0000] {taskinstance.py:2614} INFO - Dependencies all met for dep_context=non-requeueable deps ti=<TaskInstance: my_dag_name.insert_query_job manual__2025-04-03T09:21:29.742087+00:00 [queued]>
[2025-04-03T09:22:00.240+0000] {taskinstance.py:2614} INFO - Dependencies all met for dep_context=requeueable deps ti=<TaskInstance: my_dag_name.insert_query_job manual__2025-04-03T09:21:29.742087+00:00 [queued]>
[2025-04-03T09:22:00.240+0000] {taskinstance.py:2867} INFO - Starting attempt 1 of 1
[2025-04-03T09:22:00.261+0000] {taskinstance.py:2890} INFO - Executing <Task(BigQueryInsertJobOperator): insert_query_job> on 2025-04-03 09:21:29.742087+00:00
[2025-04-03T09:22:00.273+0000] {warnings.py:112} WARNING - /home/***/.local/lib/python3.12/site-packages/***/task/task_runner/standard_task_runner.py:70: DeprecationWarning: This process (pid=554) is multi-threaded, use of fork() may lead to deadlocks in the child.
  pid = os.fork()

[2025-04-03T09:22:00.276+0000] {standard_task_runner.py:72} INFO - Started process 556 to run task
[2025-04-03T09:22:00.278+0000] {standard_task_runner.py:104} INFO - Running: ['***', 'tasks', 'run', 'my_dag_name', 'insert_query_job', 'manual__2025-04-03T09:21:29.742087+00:00', '--job-id', '31', '--raw', '--subdir', 'DAGS_FOLDER/intermediaire_table.py', '--cfg-path', '/tmp/tmpz2sv_o5y']
[2025-04-03T09:22:00.280+0000] {standard_task_runner.py:105} INFO - Job 31: Subtask insert_query_job
[2025-04-03T09:22:00.350+0000] {task_command.py:467} INFO - Running <TaskInstance: my_dag_name.insert_query_job manual__2025-04-03T09:21:29.742087+00:00 [running]> on host d6badcb20287
[2025-04-03T09:22:00.498+0000] {taskinstance.py:3134} INFO - Exporting env vars: AIRFLOW_CTX_DAG_OWNER='***' AIRFLOW_CTX_DAG_ID='my_dag_name' AIRFLOW_CTX_TASK_ID='insert_query_job' AIRFLOW_CTX_EXECUTION_DATE='2025-04-03T09:21:29.742087+00:00' AIRFLOW_CTX_TRY_NUMBER='1' AIRFLOW_CTX_DAG_RUN_ID='manual__2025-04-03T09:21:29.742087+00:00'
[2025-04-03T09:22:00.501+0000] {logging_mixin.py:190} INFO - Task instance is in running state
[2025-04-03T09:22:00.501+0000] {logging_mixin.py:190} INFO -  Previous state of the Task instance: queued
[2025-04-03T09:22:00.502+0000] {logging_mixin.py:190} INFO - Current task name:insert_query_job state:running start_date:2025-04-03 09:22:00.222425+00:00
[2025-04-03T09:22:00.502+0000] {logging_mixin.py:190} INFO - Dag name:my_dag_name and current dag run status:running
[2025-04-03T09:22:00.502+0000] {taskinstance.py:732} INFO - ::endgroup::
[2025-04-03T09:22:00.532+0000] {taskinstance.py:3313} ERROR - Task failed with exception
Traceback (most recent call last):
  File "/home/airflow/.local/lib/python3.12/site-packages/airflow/models/taskinstance.py", line 768, in _execute_task
    result = _execute_callable(context=context, **execute_callable_kwargs)
             ^^^^^^^^^^^^^^^^^^^^^^^^^^^^^^^^^^^^^^^^^^^^^^^^^^^^^^^^^^^^^
  File "/home/airflow/.local/lib/python3.12/site-packages/airflow/models/taskinstance.py", line 734, in _execute_callable
    return ExecutionCallableRunner(
           ^^^^^^^^^^^^^^^^^^^^^^^^
  File "/home/airflow/.local/lib/python3.12/site-packages/airflow/utils/operator_helpers.py", line 252, in run
    return self.func(*args, **kwargs)
           ^^^^^^^^^^^^^^^^^^^^^^^^^^
  File "/home/airflow/.local/lib/python3.12/site-packages/airflow/models/baseoperator.py", line 424, in wrapper
    return func(self, *args, **kwargs)
           ^^^^^^^^^^^^^^^^^^^^^^^^^^^
  File "/home/airflow/.local/lib/python3.12/site-packages/airflow/providers/google/cloud/operators/bigquery.py", line 2940, in execute
    hook = BigQueryHook(
           ^^^^^^^^^^^^^
  File "/home/airflow/.local/lib/python3.12/site-packages/airflow/providers/google/cloud/hooks/bigquery.py", line 162, in __init__
    super().__init__(**kwargs)
  File "/home/airflow/.local/lib/python3.12/site-packages/airflow/providers/google/common/hooks/base_google.py", line 283, in __init__
    self.extras: dict = self.get_connection(self.gcp_conn_id).extra_dejson
                        ^^^^^^^^^^^^^^^^^^^^^^^^^^^^^^^^^^^^^
  File "/home/airflow/.local/lib/python3.12/site-packages/airflow/hooks/base.py", line 83, in get_connection
    conn = Connection.get_connection_from_secrets(conn_id)
           ^^^^^^^^^^^^^^^^^^^^^^^^^^^^^^^^^^^^^^^^^^^^^^^
  File "/home/airflow/.local/lib/python3.12/site-packages/airflow/models/connection.py", line 537, in get_connection_from_secrets
    raise AirflowNotFoundException(f"The conn_id `{conn_id}` isn't defined")
airflow.exceptions.AirflowNotFoundException: The conn_id `google_cloud_default` isn't defined
[2025-04-03T09:22:00.540+0000] {logging_mixin.py:190} INFO - Task instance in failure state
[2025-04-03T09:22:00.541+0000] {logging_mixin.py:190} INFO - Task start:2025-04-03 09:22:00.222425+00:00 end:2025-04-03 09:22:00.540161+00:00 duration:0.317736
[2025-04-03T09:22:00.542+0000] {logging_mixin.py:190} INFO - Task:<Task(BigQueryInsertJobOperator): insert_query_job> dag:<DAG: my_dag_name> dagrun:<DagRun my_dag_name @ 2025-04-03 09:21:29.742087+00:00: manual__2025-04-03T09:21:29.742087+00:00, state:running, queued_at: 2025-04-03 09:21:29.755964+00:00. externally triggered: True>
[2025-04-03T09:22:00.542+0000] {logging_mixin.py:190} INFO - Failure caused by The conn_id `google_cloud_default` isn't defined
[2025-04-03T09:22:00.542+0000] {taskinstance.py:1226} INFO - Marking task as FAILED. dag_id=my_dag_name, task_id=insert_query_job, run_id=manual__2025-04-03T09:21:29.742087+00:00, execution_date=20250403T092129, start_date=20250403T092200, end_date=20250403T092200
[2025-04-03T09:22:00.582+0000] {taskinstance.py:341} INFO - ::group::Post task execution logs
[2025-04-03T09:22:00.582+0000] {standard_task_runner.py:124} ERROR - Failed to execute job 31 for task insert_query_job (The conn_id `google_cloud_default` isn't defined; 556)
Traceback (most recent call last):
  File "/home/airflow/.local/lib/python3.12/site-packages/airflow/task/task_runner/standard_task_runner.py", line 117, in _start_by_fork
    ret = args.func(args, dag=self.dag)
          ^^^^^^^^^^^^^^^^^^^^^^^^^^^^^
  File "/home/airflow/.local/lib/python3.12/site-packages/airflow/cli/cli_config.py", line 49, in command
    return func(*args, **kwargs)
           ^^^^^^^^^^^^^^^^^^^^^
  File "/home/airflow/.local/lib/python3.12/site-packages/airflow/utils/cli.py", line 116, in wrapper
    return f(*args, **kwargs)
           ^^^^^^^^^^^^^^^^^^
  File "/home/airflow/.local/lib/python3.12/site-packages/airflow/cli/commands/task_command.py", line 483, in task_run
    task_return_code = _run_task_by_selected_method(args, _dag, ti)
                       ^^^^^^^^^^^^^^^^^^^^^^^^^^^^^^^^^^^^^^^^^^^^
  File "/home/airflow/.local/lib/python3.12/site-packages/airflow/cli/commands/task_command.py", line 256, in _run_task_by_selected_method
    return _run_raw_task(args, ti)
           ^^^^^^^^^^^^^^^^^^^^^^^
  File "/home/airflow/.local/lib/python3.12/site-packages/airflow/cli/commands/task_command.py", line 341, in _run_raw_task
    return ti._run_raw_task(
           ^^^^^^^^^^^^^^^^^
  File "/home/airflow/.local/lib/python3.12/site-packages/airflow/utils/session.py", line 97, in wrapper
    return func(*args, session=session, **kwargs)
           ^^^^^^^^^^^^^^^^^^^^^^^^^^^^^^^^^^^^^^
  File "/home/airflow/.local/lib/python3.12/site-packages/airflow/models/taskinstance.py", line 3006, in _run_raw_task
    return _run_raw_task(
           ^^^^^^^^^^^^^^
  File "/home/airflow/.local/lib/python3.12/site-packages/airflow/models/taskinstance.py", line 274, in _run_raw_task
    TaskInstance._execute_task_with_callbacks(
  File "/home/airflow/.local/lib/python3.12/site-packages/airflow/models/taskinstance.py", line 3161, in _execute_task_with_callbacks
    result = self._execute_task(context, task_orig)
             ^^^^^^^^^^^^^^^^^^^^^^^^^^^^^^^^^^^^^^
  File "/home/airflow/.local/lib/python3.12/site-packages/airflow/models/taskinstance.py", line 3185, in _execute_task
    return _execute_task(self, context, task_orig)
           ^^^^^^^^^^^^^^^^^^^^^^^^^^^^^^^^^^^^^^^
  File "/home/airflow/.local/lib/python3.12/site-packages/airflow/models/taskinstance.py", line 768, in _execute_task
    result = _execute_callable(context=context, **execute_callable_kwargs)
             ^^^^^^^^^^^^^^^^^^^^^^^^^^^^^^^^^^^^^^^^^^^^^^^^^^^^^^^^^^^^^
  File "/home/airflow/.local/lib/python3.12/site-packages/airflow/models/taskinstance.py", line 734, in _execute_callable
    return ExecutionCallableRunner(
           ^^^^^^^^^^^^^^^^^^^^^^^^
  File "/home/airflow/.local/lib/python3.12/site-packages/airflow/utils/operator_helpers.py", line 252, in run
    return self.func(*args, **kwargs)
           ^^^^^^^^^^^^^^^^^^^^^^^^^^
  File "/home/airflow/.local/lib/python3.12/site-packages/airflow/models/baseoperator.py", line 424, in wrapper
    return func(self, *args, **kwargs)
           ^^^^^^^^^^^^^^^^^^^^^^^^^^^
  File "/home/airflow/.local/lib/python3.12/site-packages/airflow/providers/google/cloud/operators/bigquery.py", line 2940, in execute
    hook = BigQueryHook(
           ^^^^^^^^^^^^^
  File "/home/airflow/.local/lib/python3.12/site-packages/airflow/providers/google/cloud/hooks/bigquery.py", line 162, in __init__
    super().__init__(**kwargs)
  File "/home/airflow/.local/lib/python3.12/site-packages/airflow/providers/google/common/hooks/base_google.py", line 283, in __init__
    self.extras: dict = self.get_connection(self.gcp_conn_id).extra_dejson
                        ^^^^^^^^^^^^^^^^^^^^^^^^^^^^^^^^^^^^^
  File "/home/airflow/.local/lib/python3.12/site-packages/airflow/hooks/base.py", line 83, in get_connection
    conn = Connection.get_connection_from_secrets(conn_id)
           ^^^^^^^^^^^^^^^^^^^^^^^^^^^^^^^^^^^^^^^^^^^^^^^
  File "/home/airflow/.local/lib/python3.12/site-packages/airflow/models/connection.py", line 537, in get_connection_from_secrets
    raise AirflowNotFoundException(f"The conn_id `{conn_id}` isn't defined")
airflow.exceptions.AirflowNotFoundException: The conn_id `google_cloud_default` isn't defined
[2025-04-03T09:22:00.613+0000] {local_task_job_runner.py:266} INFO - Task exited with return code 1
[2025-04-03T09:22:00.639+0000] {taskinstance.py:3901} INFO - 0 downstream tasks scheduled from follow-on schedule check
[2025-04-03T09:22:00.642+0000] {local_task_job_runner.py:245} INFO - ::endgroup::
