[2025-04-03T11:10:31.334+0000] {local_task_job_runner.py:123} INFO - ::group::Pre task execution logs
[2025-04-03T11:10:31.383+0000] {taskinstance.py:2614} INFO - Dependencies all met for dep_context=non-requeueable deps ti=<TaskInstance: test_dag.create_table_intermediaire manual__2025-04-03T11:10:21.310888+00:00 [queued]>
[2025-04-03T11:10:31.403+0000] {taskinstance.py:2614} INFO - Dependencies all met for dep_context=requeueable deps ti=<TaskInstance: test_dag.create_table_intermediaire manual__2025-04-03T11:10:21.310888+00:00 [queued]>
[2025-04-03T11:10:31.404+0000] {taskinstance.py:2867} INFO - Starting attempt 1 of 1
[2025-04-03T11:10:31.435+0000] {taskinstance.py:2890} INFO - Executing <Task(BigQueryCreateTableOperator): create_table_intermediaire> on 2025-04-03 11:10:21.310888+00:00
[2025-04-03T11:10:31.472+0000] {warnings.py:112} WARNING - /home/***/.local/lib/python3.12/site-packages/***/task/task_runner/standard_task_runner.py:70: DeprecationWarning: This process (pid=2269) is multi-threaded, use of fork() may lead to deadlocks in the child.
  pid = os.fork()

[2025-04-03T11:10:31.478+0000] {standard_task_runner.py:72} INFO - Started process 2280 to run task
[2025-04-03T11:10:31.500+0000] {standard_task_runner.py:104} INFO - Running: ['***', 'tasks', 'run', 'test_dag', 'create_table_intermediaire', 'manual__2025-04-03T11:10:21.310888+00:00', '--job-id', '117', '--raw', '--subdir', 'DAGS_FOLDER/test.py', '--cfg-path', '/tmp/tmpwhhddisv']
[2025-04-03T11:10:31.505+0000] {standard_task_runner.py:105} INFO - Job 117: Subtask create_table_intermediaire
[2025-04-03T11:10:31.642+0000] {task_command.py:467} INFO - Running <TaskInstance: test_dag.create_table_intermediaire manual__2025-04-03T11:10:21.310888+00:00 [running]> on host d6badcb20287
[2025-04-03T11:10:31.977+0000] {taskinstance.py:3134} INFO - Exporting env vars: AIRFLOW_CTX_DAG_OWNER='***' AIRFLOW_CTX_DAG_ID='test_dag' AIRFLOW_CTX_TASK_ID='create_table_intermediaire' AIRFLOW_CTX_EXECUTION_DATE='2025-04-03T11:10:21.310888+00:00' AIRFLOW_CTX_TRY_NUMBER='1' AIRFLOW_CTX_DAG_RUN_ID='manual__2025-04-03T11:10:21.310888+00:00'
[2025-04-03T11:10:31.990+0000] {logging_mixin.py:190} INFO - Task instance is in running state
[2025-04-03T11:10:31.990+0000] {logging_mixin.py:190} INFO -  Previous state of the Task instance: queued
[2025-04-03T11:10:31.993+0000] {logging_mixin.py:190} INFO - Current task name:create_table_intermediaire state:running start_date:2025-04-03 11:10:31.384596+00:00
[2025-04-03T11:10:31.994+0000] {logging_mixin.py:190} INFO - Dag name:test_dag and current dag run status:running
[2025-04-03T11:10:31.994+0000] {taskinstance.py:732} INFO - ::endgroup::
[2025-04-03T11:10:32.031+0000] {base.py:84} INFO - Retrieving connection 'gcp_conn'
[2025-04-03T11:10:32.032+0000] {bigquery.py:1274} INFO - Creating table...
[2025-04-03T11:10:32.155+0000] {taskinstance.py:3313} ERROR - Task failed with exception
Traceback (most recent call last):
  File "/home/airflow/.local/lib/python3.12/site-packages/airflow/models/taskinstance.py", line 768, in _execute_task
    result = _execute_callable(context=context, **execute_callable_kwargs)
             ^^^^^^^^^^^^^^^^^^^^^^^^^^^^^^^^^^^^^^^^^^^^^^^^^^^^^^^^^^^^^
  File "/home/airflow/.local/lib/python3.12/site-packages/airflow/models/taskinstance.py", line 734, in _execute_callable
    return ExecutionCallableRunner(
           ^^^^^^^^^^^^^^^^^^^^^^^^
  File "/home/airflow/.local/lib/python3.12/site-packages/airflow/utils/operator_helpers.py", line 252, in run
    return self.func(*args, **kwargs)
           ^^^^^^^^^^^^^^^^^^^^^^^^^^
  File "/home/airflow/.local/lib/python3.12/site-packages/airflow/models/baseoperator.py", line 424, in wrapper
    return func(self, *args, **kwargs)
           ^^^^^^^^^^^^^^^^^^^^^^^^^^^
  File "/home/airflow/.local/lib/python3.12/site-packages/airflow/providers/google/cloud/operators/bigquery.py", line 1275, in execute
    self._table = bq_hook.create_table(
                  ^^^^^^^^^^^^^^^^^^^^^
  File "/home/airflow/.local/lib/python3.12/site-packages/airflow/providers/google/common/hooks/base_google.py", line 553, in inner_wrapper
    return func(self, *args, **kwargs)
           ^^^^^^^^^^^^^^^^^^^^^^^^^^^
  File "/home/airflow/.local/lib/python3.12/site-packages/airflow/providers/google/cloud/hooks/bigquery.py", line 522, in create_table
    table_resource_final = {**table_resource, **_table_resource}  # type: ignore
                           ^^^^^^^^^^^^^^^^^^^^^^^^^^^^^^^^^^^^^
TypeError: 'set' object is not a mapping
[2025-04-03T11:10:32.176+0000] {logging_mixin.py:190} INFO - Task instance in failure state
[2025-04-03T11:10:32.177+0000] {logging_mixin.py:190} INFO - Task start:2025-04-03 11:10:31.384596+00:00 end:2025-04-03 11:10:32.175704+00:00 duration:0.791108
[2025-04-03T11:10:32.178+0000] {logging_mixin.py:190} INFO - Task:<Task(BigQueryCreateTableOperator): create_table_intermediaire> dag:<DAG: test_dag> dagrun:<DagRun test_dag @ 2025-04-03 11:10:21.310888+00:00: manual__2025-04-03T11:10:21.310888+00:00, state:running, queued_at: 2025-04-03 11:10:21.347385+00:00. externally triggered: True>
[2025-04-03T11:10:32.178+0000] {logging_mixin.py:190} INFO - Failure caused by 'set' object is not a mapping
[2025-04-03T11:10:32.179+0000] {taskinstance.py:1226} INFO - Marking task as FAILED. dag_id=test_dag, task_id=create_table_intermediaire, run_id=manual__2025-04-03T11:10:21.310888+00:00, execution_date=20250403T111021, start_date=20250403T111031, end_date=20250403T111032
[2025-04-03T11:10:32.245+0000] {taskinstance.py:341} INFO - ::group::Post task execution logs
[2025-04-03T11:10:32.246+0000] {standard_task_runner.py:124} ERROR - Failed to execute job 117 for task create_table_intermediaire ('set' object is not a mapping; 2280)
Traceback (most recent call last):
  File "/home/airflow/.local/lib/python3.12/site-packages/airflow/task/task_runner/standard_task_runner.py", line 117, in _start_by_fork
    ret = args.func(args, dag=self.dag)
          ^^^^^^^^^^^^^^^^^^^^^^^^^^^^^
  File "/home/airflow/.local/lib/python3.12/site-packages/airflow/cli/cli_config.py", line 49, in command
    return func(*args, **kwargs)
           ^^^^^^^^^^^^^^^^^^^^^
  File "/home/airflow/.local/lib/python3.12/site-packages/airflow/utils/cli.py", line 116, in wrapper
    return f(*args, **kwargs)
           ^^^^^^^^^^^^^^^^^^
  File "/home/airflow/.local/lib/python3.12/site-packages/airflow/cli/commands/task_command.py", line 483, in task_run
    task_return_code = _run_task_by_selected_method(args, _dag, ti)
                       ^^^^^^^^^^^^^^^^^^^^^^^^^^^^^^^^^^^^^^^^^^^^
  File "/home/airflow/.local/lib/python3.12/site-packages/airflow/cli/commands/task_command.py", line 256, in _run_task_by_selected_method
    return _run_raw_task(args, ti)
           ^^^^^^^^^^^^^^^^^^^^^^^
  File "/home/airflow/.local/lib/python3.12/site-packages/airflow/cli/commands/task_command.py", line 341, in _run_raw_task
    return ti._run_raw_task(
           ^^^^^^^^^^^^^^^^^
  File "/home/airflow/.local/lib/python3.12/site-packages/airflow/utils/session.py", line 97, in wrapper
    return func(*args, session=session, **kwargs)
           ^^^^^^^^^^^^^^^^^^^^^^^^^^^^^^^^^^^^^^
  File "/home/airflow/.local/lib/python3.12/site-packages/airflow/models/taskinstance.py", line 3006, in _run_raw_task
    return _run_raw_task(
           ^^^^^^^^^^^^^^
  File "/home/airflow/.local/lib/python3.12/site-packages/airflow/models/taskinstance.py", line 274, in _run_raw_task
    TaskInstance._execute_task_with_callbacks(
  File "/home/airflow/.local/lib/python3.12/site-packages/airflow/models/taskinstance.py", line 3161, in _execute_task_with_callbacks
    result = self._execute_task(context, task_orig)
             ^^^^^^^^^^^^^^^^^^^^^^^^^^^^^^^^^^^^^^
  File "/home/airflow/.local/lib/python3.12/site-packages/airflow/models/taskinstance.py", line 3185, in _execute_task
    return _execute_task(self, context, task_orig)
           ^^^^^^^^^^^^^^^^^^^^^^^^^^^^^^^^^^^^^^^
  File "/home/airflow/.local/lib/python3.12/site-packages/airflow/models/taskinstance.py", line 768, in _execute_task
    result = _execute_callable(context=context, **execute_callable_kwargs)
             ^^^^^^^^^^^^^^^^^^^^^^^^^^^^^^^^^^^^^^^^^^^^^^^^^^^^^^^^^^^^^
  File "/home/airflow/.local/lib/python3.12/site-packages/airflow/models/taskinstance.py", line 734, in _execute_callable
    return ExecutionCallableRunner(
           ^^^^^^^^^^^^^^^^^^^^^^^^
  File "/home/airflow/.local/lib/python3.12/site-packages/airflow/utils/operator_helpers.py", line 252, in run
    return self.func(*args, **kwargs)
           ^^^^^^^^^^^^^^^^^^^^^^^^^^
  File "/home/airflow/.local/lib/python3.12/site-packages/airflow/models/baseoperator.py", line 424, in wrapper
    return func(self, *args, **kwargs)
           ^^^^^^^^^^^^^^^^^^^^^^^^^^^
  File "/home/airflow/.local/lib/python3.12/site-packages/airflow/providers/google/cloud/operators/bigquery.py", line 1275, in execute
    self._table = bq_hook.create_table(
                  ^^^^^^^^^^^^^^^^^^^^^
  File "/home/airflow/.local/lib/python3.12/site-packages/airflow/providers/google/common/hooks/base_google.py", line 553, in inner_wrapper
    return func(self, *args, **kwargs)
           ^^^^^^^^^^^^^^^^^^^^^^^^^^^
  File "/home/airflow/.local/lib/python3.12/site-packages/airflow/providers/google/cloud/hooks/bigquery.py", line 522, in create_table
    table_resource_final = {**table_resource, **_table_resource}  # type: ignore
                           ^^^^^^^^^^^^^^^^^^^^^^^^^^^^^^^^^^^^^
TypeError: 'set' object is not a mapping
[2025-04-03T11:10:32.303+0000] {local_task_job_runner.py:266} INFO - Task exited with return code 1
[2025-04-03T11:10:32.366+0000] {taskinstance.py:3901} INFO - 0 downstream tasks scheduled from follow-on schedule check
[2025-04-03T11:10:32.373+0000] {local_task_job_runner.py:245} INFO - ::endgroup::
