[2025-04-03T09:17:56.185+0000] {local_task_job_runner.py:123} INFO - ::group::Pre task execution logs
[2025-04-03T09:17:56.211+0000] {taskinstance.py:2614} INFO - Dependencies all met for dep_context=non-requeueable deps ti=<TaskInstance: my_dag_name.create_table_intermediaire manual__2025-04-03T09:17:51.842610+00:00 [queued]>
[2025-04-03T09:17:56.224+0000] {taskinstance.py:2614} INFO - Dependencies all met for dep_context=requeueable deps ti=<TaskInstance: my_dag_name.create_table_intermediaire manual__2025-04-03T09:17:51.842610+00:00 [queued]>
[2025-04-03T09:17:56.224+0000] {taskinstance.py:2867} INFO - Starting attempt 1 of 1
[2025-04-03T09:17:56.249+0000] {taskinstance.py:2890} INFO - Executing <Task(BigQueryCreateTableOperator): create_table_intermediaire> on 2025-04-03 09:17:51.842610+00:00
[2025-04-03T09:17:56.261+0000] {warnings.py:112} WARNING - /home/***/.local/lib/python3.12/site-packages/***/task/task_runner/standard_task_runner.py:70: DeprecationWarning: This process (pid=480) is multi-threaded, use of fork() may lead to deadlocks in the child.
  pid = os.fork()

[2025-04-03T09:17:56.264+0000] {standard_task_runner.py:72} INFO - Started process 482 to run task
[2025-04-03T09:17:56.266+0000] {standard_task_runner.py:104} INFO - Running: ['***', 'tasks', 'run', 'my_dag_name', 'create_table_intermediaire', 'manual__2025-04-03T09:17:51.842610+00:00', '--job-id', '26', '--raw', '--subdir', 'DAGS_FOLDER/intermediaire_table.py', '--cfg-path', '/tmp/tmpds430gn2']
[2025-04-03T09:17:56.268+0000] {standard_task_runner.py:105} INFO - Job 26: Subtask create_table_intermediaire
[2025-04-03T09:17:56.338+0000] {task_command.py:467} INFO - Running <TaskInstance: my_dag_name.create_table_intermediaire manual__2025-04-03T09:17:51.842610+00:00 [running]> on host d6badcb20287
[2025-04-03T09:17:56.485+0000] {taskinstance.py:3134} INFO - Exporting env vars: AIRFLOW_CTX_DAG_OWNER='***' AIRFLOW_CTX_DAG_ID='my_dag_name' AIRFLOW_CTX_TASK_ID='create_table_intermediaire' AIRFLOW_CTX_EXECUTION_DATE='2025-04-03T09:17:51.842610+00:00' AIRFLOW_CTX_TRY_NUMBER='1' AIRFLOW_CTX_DAG_RUN_ID='manual__2025-04-03T09:17:51.842610+00:00'
[2025-04-03T09:17:56.488+0000] {logging_mixin.py:190} INFO - Task instance is in running state
[2025-04-03T09:17:56.489+0000] {logging_mixin.py:190} INFO -  Previous state of the Task instance: queued
[2025-04-03T09:17:56.489+0000] {logging_mixin.py:190} INFO - Current task name:create_table_intermediaire state:running start_date:2025-04-03 09:17:56.211620+00:00
[2025-04-03T09:17:56.489+0000] {logging_mixin.py:190} INFO - Dag name:my_dag_name and current dag run status:running
[2025-04-03T09:17:56.490+0000] {taskinstance.py:732} INFO - ::endgroup::
[2025-04-03T09:17:56.518+0000] {taskinstance.py:3313} ERROR - Task failed with exception
Traceback (most recent call last):
  File "/home/airflow/.local/lib/python3.12/site-packages/airflow/models/taskinstance.py", line 768, in _execute_task
    result = _execute_callable(context=context, **execute_callable_kwargs)
             ^^^^^^^^^^^^^^^^^^^^^^^^^^^^^^^^^^^^^^^^^^^^^^^^^^^^^^^^^^^^^
  File "/home/airflow/.local/lib/python3.12/site-packages/airflow/models/taskinstance.py", line 734, in _execute_callable
    return ExecutionCallableRunner(
           ^^^^^^^^^^^^^^^^^^^^^^^^
  File "/home/airflow/.local/lib/python3.12/site-packages/airflow/utils/operator_helpers.py", line 252, in run
    return self.func(*args, **kwargs)
           ^^^^^^^^^^^^^^^^^^^^^^^^^^
  File "/home/airflow/.local/lib/python3.12/site-packages/airflow/models/baseoperator.py", line 424, in wrapper
    return func(self, *args, **kwargs)
           ^^^^^^^^^^^^^^^^^^^^^^^^^^^
  File "/home/airflow/.local/lib/python3.12/site-packages/airflow/providers/google/cloud/operators/bigquery.py", line 1257, in execute
    bq_hook = BigQueryHook(
              ^^^^^^^^^^^^^
  File "/home/airflow/.local/lib/python3.12/site-packages/airflow/providers/google/cloud/hooks/bigquery.py", line 162, in __init__
    super().__init__(**kwargs)
  File "/home/airflow/.local/lib/python3.12/site-packages/airflow/providers/google/common/hooks/base_google.py", line 283, in __init__
    self.extras: dict = self.get_connection(self.gcp_conn_id).extra_dejson
                        ^^^^^^^^^^^^^^^^^^^^^^^^^^^^^^^^^^^^^
  File "/home/airflow/.local/lib/python3.12/site-packages/airflow/hooks/base.py", line 83, in get_connection
    conn = Connection.get_connection_from_secrets(conn_id)
           ^^^^^^^^^^^^^^^^^^^^^^^^^^^^^^^^^^^^^^^^^^^^^^^
  File "/home/airflow/.local/lib/python3.12/site-packages/airflow/models/connection.py", line 537, in get_connection_from_secrets
    raise AirflowNotFoundException(f"The conn_id `{conn_id}` isn't defined")
airflow.exceptions.AirflowNotFoundException: The conn_id `gcp_co` isn't defined
[2025-04-03T09:17:56.527+0000] {logging_mixin.py:190} INFO - Task instance in failure state
[2025-04-03T09:17:56.527+0000] {logging_mixin.py:190} INFO - Task start:2025-04-03 09:17:56.211620+00:00 end:2025-04-03 09:17:56.526416+00:00 duration:0.314796
[2025-04-03T09:17:56.528+0000] {logging_mixin.py:190} INFO - Task:<Task(BigQueryCreateTableOperator): create_table_intermediaire> dag:<DAG: my_dag_name> dagrun:<DagRun my_dag_name @ 2025-04-03 09:17:51.842610+00:00: manual__2025-04-03T09:17:51.842610+00:00, state:running, queued_at: 2025-04-03 09:17:51.853672+00:00. externally triggered: True>
[2025-04-03T09:17:56.528+0000] {logging_mixin.py:190} INFO - Failure caused by The conn_id `gcp_co` isn't defined
[2025-04-03T09:17:56.528+0000] {taskinstance.py:1226} INFO - Marking task as FAILED. dag_id=my_dag_name, task_id=create_table_intermediaire, run_id=manual__2025-04-03T09:17:51.842610+00:00, execution_date=20250403T091751, start_date=20250403T091756, end_date=20250403T091756
[2025-04-03T09:17:56.572+0000] {taskinstance.py:341} INFO - ::group::Post task execution logs
[2025-04-03T09:17:56.573+0000] {standard_task_runner.py:124} ERROR - Failed to execute job 26 for task create_table_intermediaire (The conn_id `gcp_co` isn't defined; 482)
Traceback (most recent call last):
  File "/home/airflow/.local/lib/python3.12/site-packages/airflow/task/task_runner/standard_task_runner.py", line 117, in _start_by_fork
    ret = args.func(args, dag=self.dag)
          ^^^^^^^^^^^^^^^^^^^^^^^^^^^^^
  File "/home/airflow/.local/lib/python3.12/site-packages/airflow/cli/cli_config.py", line 49, in command
    return func(*args, **kwargs)
           ^^^^^^^^^^^^^^^^^^^^^
  File "/home/airflow/.local/lib/python3.12/site-packages/airflow/utils/cli.py", line 116, in wrapper
    return f(*args, **kwargs)
           ^^^^^^^^^^^^^^^^^^
  File "/home/airflow/.local/lib/python3.12/site-packages/airflow/cli/commands/task_command.py", line 483, in task_run
    task_return_code = _run_task_by_selected_method(args, _dag, ti)
                       ^^^^^^^^^^^^^^^^^^^^^^^^^^^^^^^^^^^^^^^^^^^^
  File "/home/airflow/.local/lib/python3.12/site-packages/airflow/cli/commands/task_command.py", line 256, in _run_task_by_selected_method
    return _run_raw_task(args, ti)
           ^^^^^^^^^^^^^^^^^^^^^^^
  File "/home/airflow/.local/lib/python3.12/site-packages/airflow/cli/commands/task_command.py", line 341, in _run_raw_task
    return ti._run_raw_task(
           ^^^^^^^^^^^^^^^^^
  File "/home/airflow/.local/lib/python3.12/site-packages/airflow/utils/session.py", line 97, in wrapper
    return func(*args, session=session, **kwargs)
           ^^^^^^^^^^^^^^^^^^^^^^^^^^^^^^^^^^^^^^
  File "/home/airflow/.local/lib/python3.12/site-packages/airflow/models/taskinstance.py", line 3006, in _run_raw_task
    return _run_raw_task(
           ^^^^^^^^^^^^^^
  File "/home/airflow/.local/lib/python3.12/site-packages/airflow/models/taskinstance.py", line 274, in _run_raw_task
    TaskInstance._execute_task_with_callbacks(
  File "/home/airflow/.local/lib/python3.12/site-packages/airflow/models/taskinstance.py", line 3161, in _execute_task_with_callbacks
    result = self._execute_task(context, task_orig)
             ^^^^^^^^^^^^^^^^^^^^^^^^^^^^^^^^^^^^^^
  File "/home/airflow/.local/lib/python3.12/site-packages/airflow/models/taskinstance.py", line 3185, in _execute_task
    return _execute_task(self, context, task_orig)
           ^^^^^^^^^^^^^^^^^^^^^^^^^^^^^^^^^^^^^^^
  File "/home/airflow/.local/lib/python3.12/site-packages/airflow/models/taskinstance.py", line 768, in _execute_task
    result = _execute_callable(context=context, **execute_callable_kwargs)
             ^^^^^^^^^^^^^^^^^^^^^^^^^^^^^^^^^^^^^^^^^^^^^^^^^^^^^^^^^^^^^
  File "/home/airflow/.local/lib/python3.12/site-packages/airflow/models/taskinstance.py", line 734, in _execute_callable
    return ExecutionCallableRunner(
           ^^^^^^^^^^^^^^^^^^^^^^^^
  File "/home/airflow/.local/lib/python3.12/site-packages/airflow/utils/operator_helpers.py", line 252, in run
    return self.func(*args, **kwargs)
           ^^^^^^^^^^^^^^^^^^^^^^^^^^
  File "/home/airflow/.local/lib/python3.12/site-packages/airflow/models/baseoperator.py", line 424, in wrapper
    return func(self, *args, **kwargs)
           ^^^^^^^^^^^^^^^^^^^^^^^^^^^
  File "/home/airflow/.local/lib/python3.12/site-packages/airflow/providers/google/cloud/operators/bigquery.py", line 1257, in execute
    bq_hook = BigQueryHook(
              ^^^^^^^^^^^^^
  File "/home/airflow/.local/lib/python3.12/site-packages/airflow/providers/google/cloud/hooks/bigquery.py", line 162, in __init__
    super().__init__(**kwargs)
  File "/home/airflow/.local/lib/python3.12/site-packages/airflow/providers/google/common/hooks/base_google.py", line 283, in __init__
    self.extras: dict = self.get_connection(self.gcp_conn_id).extra_dejson
                        ^^^^^^^^^^^^^^^^^^^^^^^^^^^^^^^^^^^^^
  File "/home/airflow/.local/lib/python3.12/site-packages/airflow/hooks/base.py", line 83, in get_connection
    conn = Connection.get_connection_from_secrets(conn_id)
           ^^^^^^^^^^^^^^^^^^^^^^^^^^^^^^^^^^^^^^^^^^^^^^^
  File "/home/airflow/.local/lib/python3.12/site-packages/airflow/models/connection.py", line 537, in get_connection_from_secrets
    raise AirflowNotFoundException(f"The conn_id `{conn_id}` isn't defined")
airflow.exceptions.AirflowNotFoundException: The conn_id `gcp_co` isn't defined
[2025-04-03T09:17:56.601+0000] {local_task_job_runner.py:266} INFO - Task exited with return code 1
[2025-04-03T09:17:56.644+0000] {taskinstance.py:3901} INFO - 0 downstream tasks scheduled from follow-on schedule check
[2025-04-03T09:17:56.650+0000] {local_task_job_runner.py:245} INFO - ::endgroup::
