[2025-04-03T10:53:58.378+0000] {local_task_job_runner.py:123} INFO - ::group::Pre task execution logs
[2025-04-03T10:53:58.412+0000] {taskinstance.py:2614} INFO - Dependencies all met for dep_context=non-requeueable deps ti=<TaskInstance: my_dag_name.create_table_intermediaire manual__2025-04-03T10:53:54.038217+00:00 [queued]>
[2025-04-03T10:53:58.426+0000] {taskinstance.py:2614} INFO - Dependencies all met for dep_context=requeueable deps ti=<TaskInstance: my_dag_name.create_table_intermediaire manual__2025-04-03T10:53:54.038217+00:00 [queued]>
[2025-04-03T10:53:58.427+0000] {taskinstance.py:2867} INFO - Starting attempt 1 of 1
[2025-04-03T10:53:58.449+0000] {taskinstance.py:2890} INFO - Executing <Task(BigQueryCreateTableOperator): create_table_intermediaire> on 2025-04-03 10:53:54.038217+00:00
[2025-04-03T10:53:58.463+0000] {warnings.py:112} WARNING - /home/***/.local/lib/python3.12/site-packages/***/task/task_runner/standard_task_runner.py:70: DeprecationWarning: This process (pid=1962) is multi-threaded, use of fork() may lead to deadlocks in the child.
  pid = os.fork()

[2025-04-03T10:53:58.466+0000] {standard_task_runner.py:72} INFO - Started process 1964 to run task
[2025-04-03T10:53:58.470+0000] {standard_task_runner.py:104} INFO - Running: ['***', 'tasks', 'run', 'my_dag_name', 'create_table_intermediaire', 'manual__2025-04-03T10:53:54.038217+00:00', '--job-id', '94', '--raw', '--subdir', 'DAGS_FOLDER/intermediaire_table.py', '--cfg-path', '/tmp/tmpqv2cjoyx']
[2025-04-03T10:53:58.472+0000] {standard_task_runner.py:105} INFO - Job 94: Subtask create_table_intermediaire
[2025-04-03T10:53:58.551+0000] {task_command.py:467} INFO - Running <TaskInstance: my_dag_name.create_table_intermediaire manual__2025-04-03T10:53:54.038217+00:00 [running]> on host d6badcb20287
[2025-04-03T10:53:58.808+0000] {taskinstance.py:3134} INFO - Exporting env vars: AIRFLOW_CTX_DAG_OWNER='***' AIRFLOW_CTX_DAG_ID='my_dag_name' AIRFLOW_CTX_TASK_ID='create_table_intermediaire' AIRFLOW_CTX_EXECUTION_DATE='2025-04-03T10:53:54.038217+00:00' AIRFLOW_CTX_TRY_NUMBER='1' AIRFLOW_CTX_DAG_RUN_ID='manual__2025-04-03T10:53:54.038217+00:00'
[2025-04-03T10:53:58.811+0000] {logging_mixin.py:190} INFO - Task instance is in running state
[2025-04-03T10:53:58.812+0000] {logging_mixin.py:190} INFO -  Previous state of the Task instance: queued
[2025-04-03T10:53:58.812+0000] {logging_mixin.py:190} INFO - Current task name:create_table_intermediaire state:running start_date:2025-04-03 10:53:58.413423+00:00
[2025-04-03T10:53:58.813+0000] {logging_mixin.py:190} INFO - Dag name:my_dag_name and current dag run status:running
[2025-04-03T10:53:58.813+0000] {taskinstance.py:732} INFO - ::endgroup::
[2025-04-03T10:53:58.852+0000] {base.py:84} INFO - Retrieving connection 'gcp_conn'
[2025-04-03T10:53:58.852+0000] {bigquery.py:1274} INFO - Creating table...
[2025-04-03T10:53:59.334+0000] {taskinstance.py:3313} ERROR - Task failed with exception
Traceback (most recent call last):
  File "/home/airflow/.local/lib/python3.12/site-packages/airflow/models/taskinstance.py", line 768, in _execute_task
    result = _execute_callable(context=context, **execute_callable_kwargs)
             ^^^^^^^^^^^^^^^^^^^^^^^^^^^^^^^^^^^^^^^^^^^^^^^^^^^^^^^^^^^^^
  File "/home/airflow/.local/lib/python3.12/site-packages/airflow/models/taskinstance.py", line 734, in _execute_callable
    return ExecutionCallableRunner(
           ^^^^^^^^^^^^^^^^^^^^^^^^
  File "/home/airflow/.local/lib/python3.12/site-packages/airflow/utils/operator_helpers.py", line 252, in run
    return self.func(*args, **kwargs)
           ^^^^^^^^^^^^^^^^^^^^^^^^^^
  File "/home/airflow/.local/lib/python3.12/site-packages/airflow/models/baseoperator.py", line 424, in wrapper
    return func(self, *args, **kwargs)
           ^^^^^^^^^^^^^^^^^^^^^^^^^^^
  File "/home/airflow/.local/lib/python3.12/site-packages/airflow/providers/google/cloud/operators/bigquery.py", line 1275, in execute
    self._table = bq_hook.create_table(
                  ^^^^^^^^^^^^^^^^^^^^^
  File "/home/airflow/.local/lib/python3.12/site-packages/airflow/providers/google/common/hooks/base_google.py", line 553, in inner_wrapper
    return func(self, *args, **kwargs)
           ^^^^^^^^^^^^^^^^^^^^^^^^^^^
  File "/home/airflow/.local/lib/python3.12/site-packages/airflow/providers/google/cloud/hooks/bigquery.py", line 530, in create_table
    result = self.get_client(project_id=project_id, location=location).create_table(
             ^^^^^^^^^^^^^^^^^^^^^^^^^^^^^^^^^^^^^^^^^^^^^^^^^^^^^^^^^^^^^^^^^^^^^^^
  File "/home/airflow/.local/lib/python3.12/site-packages/google/cloud/bigquery/client.py", line 797, in create_table
    api_response = self._call_api(
                   ^^^^^^^^^^^^^^^
  File "/home/airflow/.local/lib/python3.12/site-packages/google/cloud/bigquery/client.py", line 831, in _call_api
    return call()
           ^^^^^^
  File "/home/airflow/.local/lib/python3.12/site-packages/google/api_core/retry/retry_unary.py", line 293, in retry_wrapped_func
    return retry_target(
           ^^^^^^^^^^^^^
  File "/home/airflow/.local/lib/python3.12/site-packages/google/api_core/retry/retry_unary.py", line 153, in retry_target
    _retry_error_helper(
  File "/home/airflow/.local/lib/python3.12/site-packages/google/api_core/retry/retry_base.py", line 212, in _retry_error_helper
    raise final_exc from source_exc
  File "/home/airflow/.local/lib/python3.12/site-packages/google/api_core/retry/retry_unary.py", line 144, in retry_target
    result = target()
             ^^^^^^^^
  File "/home/airflow/.local/lib/python3.12/site-packages/google/cloud/_http/__init__.py", line 494, in api_request
    raise exceptions.from_http_response(response)
google.api_core.exceptions.NotFound: 404 POST https://bigquery.googleapis.com/bigquery/v2/projects/nlpfakenews/datasets/fake_news_detection/tables?prettyPrint=false: Not found: Dataset nlpfakenews:fake_news_detection
[2025-04-03T10:53:59.354+0000] {logging_mixin.py:190} INFO - Task instance in failure state
[2025-04-03T10:53:59.355+0000] {logging_mixin.py:190} INFO - Task start:2025-04-03 10:53:58.413423+00:00 end:2025-04-03 10:53:59.353621+00:00 duration:0.940198
[2025-04-03T10:53:59.355+0000] {logging_mixin.py:190} INFO - Task:<Task(BigQueryCreateTableOperator): create_table_intermediaire> dag:<DAG: my_dag_name> dagrun:<DagRun my_dag_name @ 2025-04-03 10:53:54.038217+00:00: manual__2025-04-03T10:53:54.038217+00:00, state:running, queued_at: 2025-04-03 10:53:54.061296+00:00. externally triggered: True>
[2025-04-03T10:53:59.356+0000] {logging_mixin.py:190} INFO - Failure caused by 404 POST https://bigquery.googleapis.com/bigquery/v2/projects/nlpfakenews/datasets/fake_news_detection/tables?prettyPrint=false: Not found: Dataset nlpfakenews:fake_news_detection
[2025-04-03T10:53:59.356+0000] {taskinstance.py:1226} INFO - Marking task as FAILED. dag_id=my_dag_name, task_id=create_table_intermediaire, run_id=manual__2025-04-03T10:53:54.038217+00:00, execution_date=20250403T105354, start_date=20250403T105358, end_date=20250403T105359
[2025-04-03T10:53:59.402+0000] {taskinstance.py:341} INFO - ::group::Post task execution logs
[2025-04-03T10:53:59.403+0000] {standard_task_runner.py:124} ERROR - Failed to execute job 94 for task create_table_intermediaire (404 POST https://bigquery.googleapis.com/bigquery/v2/projects/nlpfakenews/datasets/fake_news_detection/tables?prettyPrint=false: Not found: Dataset nlpfakenews:fake_news_detection; 1964)
Traceback (most recent call last):
  File "/home/airflow/.local/lib/python3.12/site-packages/airflow/task/task_runner/standard_task_runner.py", line 117, in _start_by_fork
    ret = args.func(args, dag=self.dag)
          ^^^^^^^^^^^^^^^^^^^^^^^^^^^^^
  File "/home/airflow/.local/lib/python3.12/site-packages/airflow/cli/cli_config.py", line 49, in command
    return func(*args, **kwargs)
           ^^^^^^^^^^^^^^^^^^^^^
  File "/home/airflow/.local/lib/python3.12/site-packages/airflow/utils/cli.py", line 116, in wrapper
    return f(*args, **kwargs)
           ^^^^^^^^^^^^^^^^^^
  File "/home/airflow/.local/lib/python3.12/site-packages/airflow/cli/commands/task_command.py", line 483, in task_run
    task_return_code = _run_task_by_selected_method(args, _dag, ti)
                       ^^^^^^^^^^^^^^^^^^^^^^^^^^^^^^^^^^^^^^^^^^^^
  File "/home/airflow/.local/lib/python3.12/site-packages/airflow/cli/commands/task_command.py", line 256, in _run_task_by_selected_method
    return _run_raw_task(args, ti)
           ^^^^^^^^^^^^^^^^^^^^^^^
  File "/home/airflow/.local/lib/python3.12/site-packages/airflow/cli/commands/task_command.py", line 341, in _run_raw_task
    return ti._run_raw_task(
           ^^^^^^^^^^^^^^^^^
  File "/home/airflow/.local/lib/python3.12/site-packages/airflow/utils/session.py", line 97, in wrapper
    return func(*args, session=session, **kwargs)
           ^^^^^^^^^^^^^^^^^^^^^^^^^^^^^^^^^^^^^^
  File "/home/airflow/.local/lib/python3.12/site-packages/airflow/models/taskinstance.py", line 3006, in _run_raw_task
    return _run_raw_task(
           ^^^^^^^^^^^^^^
  File "/home/airflow/.local/lib/python3.12/site-packages/airflow/models/taskinstance.py", line 274, in _run_raw_task
    TaskInstance._execute_task_with_callbacks(
  File "/home/airflow/.local/lib/python3.12/site-packages/airflow/models/taskinstance.py", line 3161, in _execute_task_with_callbacks
    result = self._execute_task(context, task_orig)
             ^^^^^^^^^^^^^^^^^^^^^^^^^^^^^^^^^^^^^^
  File "/home/airflow/.local/lib/python3.12/site-packages/airflow/models/taskinstance.py", line 3185, in _execute_task
    return _execute_task(self, context, task_orig)
           ^^^^^^^^^^^^^^^^^^^^^^^^^^^^^^^^^^^^^^^
  File "/home/airflow/.local/lib/python3.12/site-packages/airflow/models/taskinstance.py", line 768, in _execute_task
    result = _execute_callable(context=context, **execute_callable_kwargs)
             ^^^^^^^^^^^^^^^^^^^^^^^^^^^^^^^^^^^^^^^^^^^^^^^^^^^^^^^^^^^^^
  File "/home/airflow/.local/lib/python3.12/site-packages/airflow/models/taskinstance.py", line 734, in _execute_callable
    return ExecutionCallableRunner(
           ^^^^^^^^^^^^^^^^^^^^^^^^
  File "/home/airflow/.local/lib/python3.12/site-packages/airflow/utils/operator_helpers.py", line 252, in run
    return self.func(*args, **kwargs)
           ^^^^^^^^^^^^^^^^^^^^^^^^^^
  File "/home/airflow/.local/lib/python3.12/site-packages/airflow/models/baseoperator.py", line 424, in wrapper
    return func(self, *args, **kwargs)
           ^^^^^^^^^^^^^^^^^^^^^^^^^^^
  File "/home/airflow/.local/lib/python3.12/site-packages/airflow/providers/google/cloud/operators/bigquery.py", line 1275, in execute
    self._table = bq_hook.create_table(
                  ^^^^^^^^^^^^^^^^^^^^^
  File "/home/airflow/.local/lib/python3.12/site-packages/airflow/providers/google/common/hooks/base_google.py", line 553, in inner_wrapper
    return func(self, *args, **kwargs)
           ^^^^^^^^^^^^^^^^^^^^^^^^^^^
  File "/home/airflow/.local/lib/python3.12/site-packages/airflow/providers/google/cloud/hooks/bigquery.py", line 530, in create_table
    result = self.get_client(project_id=project_id, location=location).create_table(
             ^^^^^^^^^^^^^^^^^^^^^^^^^^^^^^^^^^^^^^^^^^^^^^^^^^^^^^^^^^^^^^^^^^^^^^^
  File "/home/airflow/.local/lib/python3.12/site-packages/google/cloud/bigquery/client.py", line 797, in create_table
    api_response = self._call_api(
                   ^^^^^^^^^^^^^^^
  File "/home/airflow/.local/lib/python3.12/site-packages/google/cloud/bigquery/client.py", line 831, in _call_api
    return call()
           ^^^^^^
  File "/home/airflow/.local/lib/python3.12/site-packages/google/api_core/retry/retry_unary.py", line 293, in retry_wrapped_func
    return retry_target(
           ^^^^^^^^^^^^^
  File "/home/airflow/.local/lib/python3.12/site-packages/google/api_core/retry/retry_unary.py", line 153, in retry_target
    _retry_error_helper(
  File "/home/airflow/.local/lib/python3.12/site-packages/google/api_core/retry/retry_base.py", line 212, in _retry_error_helper
    raise final_exc from source_exc
  File "/home/airflow/.local/lib/python3.12/site-packages/google/api_core/retry/retry_unary.py", line 144, in retry_target
    result = target()
             ^^^^^^^^
  File "/home/airflow/.local/lib/python3.12/site-packages/google/cloud/_http/__init__.py", line 494, in api_request
    raise exceptions.from_http_response(response)
google.api_core.exceptions.NotFound: 404 POST https://bigquery.googleapis.com/bigquery/v2/projects/nlpfakenews/datasets/fake_news_detection/tables?prettyPrint=false: Not found: Dataset nlpfakenews:fake_news_detection
[2025-04-03T10:53:59.453+0000] {local_task_job_runner.py:266} INFO - Task exited with return code 1
[2025-04-03T10:53:59.522+0000] {taskinstance.py:3901} INFO - 0 downstream tasks scheduled from follow-on schedule check
[2025-04-03T10:53:59.530+0000] {local_task_job_runner.py:245} INFO - ::endgroup::
